<?xml version="1.0" encoding="utf-8"?>
<!-- This URDF was automatically created by SolidWorks to URDF Exporter! Originally created by Stephen Brawner (brawner@gmail.com) 
     Commit Version: 1.6.0-4-g7f85cfe  Build Version: 1.6.7995.38578
     For more information, please see http://wiki.ros.org/sw_urdf_exporter -->
<robot
  name="quadcopter">
  
  <!-- Dummy root link to avoid KDL warning about root link with inertia -->
  <link name="base_footprint">
    <!-- No inertial properties - this is a dummy link -->
  </link>
  
  <!-- Fixed joint connecting dummy root to actual base -->
  <joint name="base_footprint_to_base" type="fixed">
    <origin xyz="0 0 0" rpy="0 0 0" />
    <parent link="base_footprint" />
    <child link="base_link" />
  </joint>
  
  <link
    name="base_link">
    <inertial>
      <origin
        xyz="-0.001341 0.0013417 -0.0029971"
        rpy="0 0 0" />
      <mass
        value="1.0" />
      <inertia
        ixx="0.00089"
        ixy="-2.5E-10"
        ixz="-1.28E-09"
        iyy="0.00042"
        iyz="-1.01E-06"
        izz="0.00119" />
    </inertial>
    <visual>
      <origin
        xyz="0 0 0"
        rpy="0 0 0" />
      <geometry>
        <mesh
          filename="package://quadcopter/meshes/base_link.STL" />
      </geometry>
      <material
        name="">
        <color
          rgba="0.2 0.2 0.2 1" />
      </material>
    </visual>
    <collision>
      <origin
        xyz="0 0 0"
        rpy="0 0 0" />
      <geometry>
        <mesh
          filename="package://quadcopter/meshes/base_link.STL" />
      </geometry>
    </collision>
  </link>
  <link
    name="link_propeller_1">
    <inertial>
      <origin
        xyz="1.0253E-07 0.014059 3.7818E-09"
        rpy="0 0 0" />
      <mass
        value="0.0024223" />
      <inertia
        ixx="9.9396E-08"
        ixy="-7.8073E-13"
        ixz="6.5339E-09"
        iyy="1.937E-06"
        iyz="6.729E-14"
        izz="1.974E-06" />
    </inertial>
    <visual>
      <origin
        xyz="0 0 0"
        rpy="0 0 0" />
      <geometry>
        <mesh
          filename="package://quadcopter/meshes/link_propeller_1.STL" />
      </geometry>
      <material
        name="">
        <color
          rgba="0.1 0.1 0.1 1" />
      </material>
    </visual>
    <collision>
      <origin
        xyz="0 0 0"
        rpy="0 0 0" />
      <geometry>
        <mesh
          filename="package://quadcopter/meshes/link_propeller_1.STL" />
      </geometry>
    </collision>
  </link>
  <joint
    name="propeller_1"
    type="continuous">
    <origin
      xyz="0.090799 0.10341 0.009"
      rpy="1.5708 0 0.14191" />
    <parent
      link="base_link" />
    <child
      link="link_propeller_1" />
    <axis
      xyz="0 0 1" />
    <limit
      effort="10"
      velocity="1000" />
    <dynamics
      damping="0.02"
      friction="0.0" />
  </joint>
  <link
    name="link_propeller_2">
    <inertial>
      <origin
        xyz="1.0253E-07 0.014059 3.7817E-09"
        rpy="0 0 0" />
      <mass
        value="0.0024223" />
      <inertia
        ixx="9.9396E-08"
        ixy="-7.8072E-13"
        ixz="6.5339E-09"
        iyy="1.937E-06"
        iyz="6.7291E-14"
        izz="1.974E-06" />
    </inertial>
    <visual>
      <origin
        xyz="0 0 0"
        rpy="0 0 0" />
      <geometry>
        <mesh
          filename="package://quadcopter/meshes/link_propeller_2.STL" />
      </geometry>
      <material
        name="">
        <color
          rgba="0.1 0.1 0.1 1" />
      </material>
    </visual>
    <collision>
      <origin
        xyz="0 0 0"
        rpy="0 0 0" />
      <geometry>
        <mesh
          filename="package://quadcopter/meshes/link_propeller_2.STL" />
      </geometry>
    </collision>
  </link>
  <joint
    name="propeller_2"
    type="continuous">
    <origin
      xyz="-0.090799 0.10341 0.009"
      rpy="1.5708 0 0" />
    <parent
      link="base_link" />
    <child
      link="link_propeller_2" />
    <axis
      xyz="0 0 1" />
    <limit
      effort="10"
      velocity="1000" />
    <dynamics
      damping="0.02"
      friction="0.0" />
  </joint>
  <link
    name="link_propeller_3">
    <inertial>
      <origin
        xyz="1.0253E-07 0.014059 3.7816E-09"
        rpy="0 0 0" />
      <mass
        value="0.0024223" />
      <inertia
        ixx="9.9396E-08"
        ixy="-7.8072E-13"
        ixz="6.5339E-09"
        iyy="1.937E-06"
        iyz="6.7292E-14"
        izz="1.974E-06" />
    </inertial>
    <visual>
      <origin
        xyz="0 0 0"
        rpy="0 0 0" />
      <geometry>
        <mesh
          filename="package://quadcopter/meshes/link_propeller_3.STL" />
      </geometry>
      <material
        name="">
        <color
          rgba="0.1 0.1 0.1 1" />
      </material>
    </visual>
    <collision>
      <origin
        xyz="0 0 0"
        rpy="0 0 0" />
      <geometry>
        <mesh
          filename="package://quadcopter/meshes/link_propeller_3.STL" />
      </geometry>
    </collision>
  </link>
  <joint
    name="propeller_3"
    type="continuous">
    <origin
      xyz="0.085895 -0.09579 0.009"
      rpy="1.5708 0 2.0866" />
    <parent
      link="base_link" />
    <child
      link="link_propeller_3" />
    <axis
      xyz="0 0 1" />
    <limit
      effort="10"
      velocity="1000" />
    <dynamics
      damping="0.02"
      friction="0.0" />
  </joint>
  <link
    name="link_propeller_4">
    <inertial>
      <origin
        xyz="1.0253E-07 0.014059 3.7817E-09"
        rpy="0 0 0" />
      <mass
        value="0.0024223" />
      <inertia
        ixx="9.9396E-08"
        ixy="-7.8072E-13"
        ixz="6.5339E-09"
        iyy="1.937E-06"
        iyz="6.7291E-14"
        izz="1.974E-06" />
    </inertial>
    <visual>
      <origin
        xyz="0 0 0"
        rpy="0 0 0" />
      <geometry>
        <mesh
          filename="package://quadcopter/meshes/link_propeller_4.STL" />
      </geometry>
      <material
        name="">
        <color
          rgba="0.1 0.1 0.1 1" />
      </material>
    </visual>
    <collision>
      <origin
        xyz="0 0 0"
        rpy="0 0 0" />
      <geometry>
        <mesh
          filename="package://quadcopter/meshes/link_propeller_4.STL" />
      </geometry>
    </collision>
  </link>
  <joint
    name="propeller_4"
    type="continuous">
    <origin
      xyz="-0.085895 -0.09579 0.009"
      rpy="1.5708 0 0.17226" />
    <parent
      link="base_link" />
    <child
      link="link_propeller_4" />
    <axis
      xyz="0 0 1" />
    <limit
      effort="10"
      velocity="1000" />
    <dynamics
      damping="0.02"
      friction="0.0" />
  </joint>
  <link
    name="link_camera">
    <inertial>
      <origin
        xyz="0 0 0"
        rpy="0 0 0" />
      <mass
        value="0.01" />
      <inertia
        ixx="1e-6"
        ixy="0"
        ixz="0"
        iyy="1e-6"
        iyz="0"
        izz="1e-6" />
    </inertial>
    <visual>
      <origin
        xyz="0 0 0"
        rpy="0 0 0" />
      <geometry>
        <mesh
          filename="package://quadcopter/meshes/link_camera.STL" />
      </geometry>
      <material
        name="">
        <color
          rgba="0.15 0.15 0.15 1" />
      </material>
    </visual>
    <collision>
      <origin
        xyz="0 0 0"
        rpy="0 0 0" />
      <geometry>
        <mesh
          filename="package://quadcopter/meshes/link_camera.STL" />
      </geometry>
    </collision>
  </link>
  <joint
    name="camera"
    type="fixed">
    <origin
      xyz="0 -0.079 0"
      rpy="-1.5708 -1.176 -1.5708" />
    <parent
      link="base_link" />
    <child
      link="link_camera" />
    <axis
      xyz="0 0 0" />
  </joint>

  <!-- Gazebo Classic-style sensor block (camera) is disabled for Gazebo Garden.
       Sensors should be added via gz-sim systems or SDF world configuration. -->
  <!--
  <gazebo reference="link_camera">
    <sensor name="camera" type="camera">
      <always_on>1</always_on>
      <update_rate>30</update_rate>
      <visualize>true</visualize>
      <topic>camera</topic>
      <camera name="head">
        <horizontal_fov>1.3962634</horizontal_fov>
        <image>
          <width>800</width>
          <height>800</height>
          <format>R8G8B8</format>
        </image>
        <clip>
          <near>0.02</near>
          <far>300</far>
        </clip>
        <noise>
          <type>gaussian</type>
          <mean>0.0</mean>
          <stddev>0.007</stddev>
        </noise>
      </camera>
    </sensor>
  </gazebo>
  -->

  <!-- Gazebo Classic-style sensor block (IMU) is disabled for Gazebo Garden.
       Add IMU via gz-sim system service or SDF world configuration. -->
  <!--
  <gazebo reference="base_link">
    <sensor name="imu" type="imu">
      <always_on>true</always_on>
      <update_rate>250</update_rate>
      <topic>/imu</topic>
      <imu>
        <angular_velocity>
          <x><noise type="gaussian"><mean>0.0</mean><stddev>0.0001</stddev></noise></x>
          <y><noise type="gaussian"><mean>0.0</mean><stddev>0.0001</stddev></noise></y>
          <z><noise type="gaussian"><mean>0.0</mean><stddev>0.0001</stddev></noise></z>
        </angular_velocity>
        <linear_acceleration>
          <x><noise type="gaussian"><mean>0.0</mean><stddev>0.01</stddev></noise></x>
          <y><noise type="gaussian"><mean>0.0</mean><stddev>0.01</stddev></noise></y>
          <z><noise type="gaussian"><mean>0.0</mean><stddev>0.01</stddev></noise></z>
        </linear_acceleration>
      </imu>
    </sensor>
  </gazebo>
  -->

  <!-- ROS2 Control Configuration for Motor Control -->
  <ros2_control name="QuadcopterSystem" type="system">
    <hardware>
      <plugin>gz_ros2_control/GazeboSimSystem</plugin>
    </hardware>
    
    <!-- Propeller Joint Control -->
    <joint name="propeller_1">
      <command_interface name="velocity">
        <param name="min">-1000</param>
        <param name="max">1000</param>
      </command_interface>
      <state_interface name="position"/>
      <state_interface name="velocity"/>
      <state_interface name="effort"/>
    </joint>
    
    <joint name="propeller_2">
      <command_interface name="velocity">
        <param name="min">-1000</param>
        <param name="max">1000</param>
      </command_interface>
      <state_interface name="position"/>
      <state_interface name="velocity"/>
      <state_interface name="effort"/>
    </joint>
    
    <joint name="propeller_3">
      <command_interface name="velocity">
        <param name="min">-1000</param>
        <param name="max">1000</param>
      </command_interface>
      <state_interface name="position"/>
      <state_interface name="velocity"/>
      <state_interface name="effort"/>
    </joint>
    
    <joint name="propeller_4">
      <command_interface name="velocity">
        <param name="min">-1000</param>
        <param name="max">1000</param>
      </command_interface>
      <state_interface name="position"/>
      <state_interface name="velocity"/>
      <state_interface name="effort"/>
    </joint>
  </ros2_control>

  <!-- Gazebo ROS2 Control System for Gazebo Garden (disabled until controllers are configured) -->
  <!--
  <gazebo>
    <plugin filename="libgz_ros2_control-system.so" name="gz_ros2_control::GazeboSimROS2ControlPlugin">
      <robot_param>robot_description</robot_param>
      <robot_param_node>robot_state_publisher</robot_param_node>
    </plugin>
  </gazebo>
  -->
  <!-- Joint State Publisher Plugin for Gazebo Garden -->
  <gazebo>
    <plugin filename="gz-sim-joint-state-publisher-system" 
            name="gz::sim::systems::JointStatePublisher">
      <topic>joint_states</topic>
      <joint_name>propeller_1</joint_name>
      <joint_name>propeller_2</joint_name>
      <joint_name>propeller_3</joint_name>
      <joint_name>propeller_4</joint_name>
    </plugin>
  </gazebo>

</robot>