<?xml version="1.0"?>
<robot name="quadcopter">
  
  <!-- Dummy base link to avoid KDL root link inertia issue -->
  <link name="world"/>
  
  <joint name="world_to_base" type="fixed">
    <parent link="world"/>
    <child link="base_link"/>
  </joint>
  
  <!-- Main drone body -->
  <link name="base_link">
    <visual>
      <origin xyz="0 0 0" rpy="0 0 0"/>
      <geometry>
        <box size="0.3 0.3 0.08"/>
      </geometry>
      <material name="red">
        <color rgba="0.8 0.1 0.1 1"/>
      </material>
    </visual>
    
    <collision>
      <origin xyz="0 0 0" rpy="0 0 0"/>
      <geometry>
        <box size="0.3 0.3 0.08"/>
      </geometry>
    </collision>
    
    <inertial>
      <origin xyz="0 0 0" rpy="0 0 0"/>
      <mass value="1.5"/>
      <!-- Proper inertia matrix for a box of 0.3x0.3x0.08m with mass 1.5kg -->
      <inertia ixx="0.0125" ixy="0.0" ixz="0.0" 
               iyy="0.0125" iyz="0.0" 
               izz="0.0225"/>
    </inertial>
  </link>
  
  <!-- Arms and Motors -->
  <!-- Front motor (X+) -->
  <link name="motor_front">
    <visual>
      <geometry>
        <cylinder radius="0.02" length="0.01"/>
      </geometry>
      <material name="black">
        <color rgba="0.1 0.1 0.1 1"/>
      </material>
    </visual>
    <collision>
      <geometry>
        <cylinder radius="0.02" length="0.01"/>
      </geometry>
    </collision>
    <inertial>
      <mass value="0.05"/>
      <inertia ixx="0.0001" ixy="0" ixz="0" iyy="0.0001" iyz="0" izz="0.0001"/>
    </inertial>
  </link>
  
  <joint name="motor_front_joint" type="continuous">
    <parent link="base_link"/>
    <child link="motor_front"/>
    <origin xyz="0.15 0 0.04" rpy="0 0 0"/>
    <axis xyz="0 0 1"/>
  </joint>
  
  <!-- Propeller for front motor -->
  <link name="prop_front">
    <visual>
      <geometry>
        <cylinder radius="0.1" length="0.005"/>
      </geometry>
      <material name="gray">
        <color rgba="0.5 0.5 0.5 0.7"/>
      </material>
    </visual>
    <inertial>
      <mass value="0.01"/>
      <inertia ixx="0.00001" ixy="0" ixz="0" iyy="0.00001" iyz="0" izz="0.00002"/>
    </inertial>
  </link>
  
  <joint name="prop_front_joint" type="fixed">
    <parent link="motor_front"/>
    <child link="prop_front"/>
    <origin xyz="0 0 0.01" rpy="0 0 0"/>
  </joint>
  
  <!-- Back motor (X-) -->
  <link name="motor_back">
    <visual>
      <geometry>
        <cylinder radius="0.02" length="0.01"/>
      </geometry>
      <material name="black">
        <color rgba="0.1 0.1 0.1 1"/>
      </material>
    </visual>
    <collision>
      <geometry>
        <cylinder radius="0.02" length="0.01"/>
      </geometry>
    </collision>
    <inertial>
      <mass value="0.05"/>
      <inertia ixx="0.0001" ixy="0" ixz="0" iyy="0.0001" iyz="0" izz="0.0001"/>
    </inertial>
  </link>
  
  <joint name="motor_back_joint" type="continuous">
    <parent link="base_link"/>
    <child link="motor_back"/>
    <origin xyz="-0.15 0 0.04" rpy="0 0 0"/>
    <axis xyz="0 0 1"/>
  </joint>
  
  <link name="prop_back">
    <visual>
      <geometry>
        <cylinder radius="0.1" length="0.005"/>
      </geometry>
      <material name="gray">
        <color rgba="0.5 0.5 0.5 0.7"/>
      </material>
    </visual>
    <inertial>
      <mass value="0.01"/>
      <inertia ixx="0.00001" ixy="0" ixz="0" iyy="0.00001" iyz="0" izz="0.00002"/>
    </inertial>
  </link>
  
  <joint name="prop_back_joint" type="fixed">
    <parent link="motor_back"/>
    <child link="prop_back"/>
    <origin xyz="0 0 0.01" rpy="0 0 0"/>
  </joint>
  
  <!-- Left motor (Y+) -->
  <link name="motor_left">
    <visual>
      <geometry>
        <cylinder radius="0.02" length="0.01"/>
      </geometry>
      <material name="black">
        <color rgba="0.1 0.1 0.1 1"/>
      </material>
    </visual>
    <collision>
      <geometry>
        <cylinder radius="0.02" length="0.01"/>
      </geometry>
    </collision>
    <inertial>
      <mass value="0.05"/>
      <inertia ixx="0.0001" ixy="0" ixz="0" iyy="0.0001" iyz="0" izz="0.0001"/>
    </inertial>
  </link>
  
  <joint name="motor_left_joint" type="continuous">
    <parent link="base_link"/>
    <child link="motor_left"/>
    <origin xyz="0 0.15 0.04" rpy="0 0 0"/>
    <axis xyz="0 0 1"/>
  </joint>
  
  <link name="prop_left">
    <visual>
      <geometry>
        <cylinder radius="0.1" length="0.005"/>
      </geometry>
      <material name="gray">
        <color rgba="0.5 0.5 0.5 0.7"/>
      </material>
    </visual>
    <inertial>
      <mass value="0.01"/>
      <inertia ixx="0.00001" ixy="0" ixz="0" iyy="0.00001" iyz="0" izz="0.00002"/>
    </inertial>
  </link>
  
  <joint name="prop_left_joint" type="fixed">
    <parent link="motor_left"/>
    <child link="prop_left"/>
    <origin xyz="0 0 0.01" rpy="0 0 0"/>
  </joint>
  
  <!-- Right motor (Y-) -->
  <link name="motor_right">
    <visual>
      <geometry>
        <cylinder radius="0.02" length="0.01"/>
      </geometry>
      <material name="black">
        <color rgba="0.1 0.1 0.1 1"/>
      </material>
    </visual>
    <collision>
      <geometry>
        <cylinder radius="0.02" length="0.01"/>
      </geometry>
    </collision>
    <inertial>
      <mass value="0.05"/>
      <inertia ixx="0.0001" ixy="0" ixz="0" iyy="0.0001" iyz="0" izz="0.0001"/>
    </inertial>
  </link>
  
  <joint name="motor_right_joint" type="continuous">
    <parent link="base_link"/>
    <child link="motor_right"/>
    <origin xyz="0 -0.15 0.04" rpy="0 0 0"/>
    <axis xyz="0 0 1"/>
  </joint>
  
  <link name="prop_right">
    <visual>
      <geometry>
        <cylinder radius="0.1" length="0.005"/>
      </geometry>
      <material name="gray">
        <color rgba="0.5 0.5 0.5 0.7"/>
      </material>
    </visual>
    <inertial>
      <mass value="0.01"/>
      <inertia ixx="0.00001" ixy="0" ixz="0" iyy="0.00001" iyz="0" izz="0.00002"/>
    </inertial>
  </link>
  
  <joint name="prop_right_joint" type="fixed">
    <parent link="motor_right"/>
    <child link="prop_right"/>
    <origin xyz="0 0 0.01" rpy="0 0 0"/>
  </joint>
  
  <!-- IMU sensor -->
  <link name="imu_link">
    <visual>
      <geometry>
        <box size="0.01 0.01 0.005"/>
      </geometry>
      <material name="blue">
        <color rgba="0 0 1 1"/>
      </material>
    </visual>
    <inertial>
      <mass value="0.001"/>
      <inertia ixx="0.00001" ixy="0" ixz="0" iyy="0.00001" iyz="0" izz="0.00001"/>
    </inertial>
  </link>
  
  <joint name="imu_joint" type="fixed">
    <parent link="base_link"/>
    <child link="imu_link"/>
    <origin xyz="0 0 0" rpy="0 0 0"/>
  </joint>
  
  <!-- Camera -->
  <link name="camera_link">
    <visual>
      <geometry>
        <box size="0.02 0.04 0.02"/>
      </geometry>
      <material name="dark_gray">
        <color rgba="0.2 0.2 0.2 1"/>
      </material>
    </visual>
    <inertial>
      <mass value="0.01"/>
      <inertia ixx="0.00001" ixy="0" ixz="0" iyy="0.00001" iyz="0" izz="0.00001"/>
    </inertial>
  </link>
  
  <joint name="camera_joint" type="fixed">
    <parent link="base_link"/>
    <child link="camera_link"/>
    <origin xyz="0.16 0 -0.02" rpy="0 0.2 0"/>
  </joint>

  <!-- Gazebo plugins -->
  <gazebo>
    <!-- IMU plugin -->
    <plugin filename="libgz-sim-imu-system.so" name="gz::sim::systems::Imu">
      <alwaysOn>true</alwaysOn>
      <updateRate>250</updateRate>
    </plugin>
    
    <!-- Multicopter control plugin -->
    <plugin filename="libgz-sim-multicopter-control-system.so" name="gz::sim::systems::MulticopterVelocityControl">
      <commandSubTopic>cmd_vel</commandSubTopic>
      <robotNamespace>drone</robotNamespace>
      <rotorConfiguration>
        <rotor>
          <jointName>motor_front_joint</jointName>
          <forceConstant>8.54858e-06</forceConstant>
          <momentConstant>0.016</momentConstant>
          <direction>1</direction>
        </rotor>
        <rotor>
          <jointName>motor_back_joint</jointName>
          <forceConstant>8.54858e-06</forceConstant>
          <momentConstant>0.016</momentConstant>
          <direction>-1</direction>
        </rotor>
        <rotor>
          <jointName>motor_left_joint</jointName>
          <forceConstant>8.54858e-06</forceConstant>
          <momentConstant>0.016</momentConstant>
          <direction>1</direction>
        </rotor>
        <rotor>
          <jointName>motor_right_joint</jointName>
          <forceConstant>8.54858e-06</forceConstant>
          <momentConstant>0.016</momentConstant>
          <direction>-1</direction>
        </rotor>
      </rotorConfiguration>
    </plugin>
  </gazebo>
  
  <!-- Color definitions for Gazebo -->
  <gazebo reference="base_link">
    <material>Gazebo/Red</material>
  </gazebo>
  
  <gazebo reference="imu_link">
    <material>Gazebo/Blue</material>
  </gazebo>
  
  <gazebo reference="camera_link">
    <material>Gazebo/Black</material>
  </gazebo>
</robot>